<robot name = "robot">
    <link name="Left_Foot">
        <inertial>
            <origin xyz="-0.25 0 0.25" rpy="0 0 0"/>
            <mass value="1" />
            <inertia ixx="100" ixy="0" ixz="0" iyy="100" iyz="0" izz="100" />
        </inertial>
        <visual>
            <origin xyz="-0.25 0 0.25" rpy="0 0 0"/>
            <geometry>
                <box size="0.5 1 0.5" />
            </geometry>
            <material name="Cyan">
                <color rgba="0 1.0 1.0 1.0"/>
            </material>
        </visual>
        <collision>
            <origin xyz="-0.25 0 0.25" rpy="0 0 0"/>
            <geometry>
                <box size="0.5 1 0.5" />
            </geometry>
        </collision>
    </link>
    <joint name="Left_Foot_Torso" type="revolute">
       <parent link="Left_Foot"/>
       <child  link="Torso"/>
       <origin rpy="0 0 0" xyz="0 0.5 0" />
       <axis xyz="0 1 0"/>
       <limit effort="0.0" lower="-3.14159" upper="3.14159" velocity="0.0"/>
    </joint>
    <link name="Torso">
        <inertial>
            <origin xyz="1 0.5 0.25" rpy="0 0 0"/>
            <mass value="1" />
            <inertia ixx="100" ixy="0" ixz="0" iyy="100" iyz="0" izz="100" />
        </inertial>
        <visual>
            <origin xyz="1 0.5 0.25" rpy="0 0 0"/>
            <geometry>
                <box size="3 1 0.5" />
            </geometry>
            <material name="Cyan">
                <color rgba="0 1.0 1.0 1.0"/>
            </material>
        </visual>
        <collision>
            <origin xyz="1 0.5 0.25" rpy="0 0 0"/>
            <geometry>
                <box size="3 1 0.5" />
            </geometry>
        </collision>
    </link>
    <joint name="Right_Foot_Torso" type="revolute">
       <parent link="Torso"/>
       <child  link="Right_Foot"/>
       <origin rpy="0 0 0" xyz="0 1.0 0" />
       <axis xyz="0 1 0"/>
       <limit effort="0.0" lower="-3.14159" upper="3.14159" velocity="0.0"/>
    </joint>
    <link name="Right_Foot">
        <inertial>
            <origin xyz="-0.25 0.5 0.25" rpy="0 0 0"/>
            <mass value="1" />
            <inertia ixx="100" ixy="0" ixz="0" iyy="100" iyz="0" izz="100" />
        </inertial>
        <visual>
            <origin xyz="-0.25 0.5 0.25" rpy="0 0 0"/>
            <geometry>
                <box size="0.5 1 0.5" />
            </geometry>
            <material name="Cyan">
                <color rgba="0 1.0 1.0 1.0"/>
            </material>
        </visual>
        <collision>
            <origin xyz="-0.25 0.5 0.25" rpy="0 0 0"/>
            <geometry>
                <box size="0.5 1 0.5" />
            </geometry>
        </collision>
    </link>
</robot>